[2024-04-12T23:19:00.372+0000] {taskinstance.py:1979} INFO - Dependencies all met for dep_context=non-requeueable deps ti=<TaskInstance: example-docker-operator-dag.print_message manual__2024-04-12T23:18:59.707108+00:00 [queued]>
[2024-04-12T23:19:00.377+0000] {taskinstance.py:1979} INFO - Dependencies all met for dep_context=requeueable deps ti=<TaskInstance: example-docker-operator-dag.print_message manual__2024-04-12T23:18:59.707108+00:00 [queued]>
[2024-04-12T23:19:00.377+0000] {taskinstance.py:2193} INFO - Starting attempt 1 of 1
[2024-04-12T23:19:00.385+0000] {taskinstance.py:2217} INFO - Executing <Task(DockerOperator): print_message> on 2024-04-12 23:18:59.707108+00:00
[2024-04-12T23:19:00.390+0000] {standard_task_runner.py:60} INFO - Started process 1166 to run task
[2024-04-12T23:19:00.395+0000] {standard_task_runner.py:87} INFO - Running: ['***', 'tasks', 'run', 'example-docker-operator-dag', 'print_message', 'manual__2024-04-12T23:18:59.707108+00:00', '--job-id', '9', '--raw', '--subdir', 'DAGS_FOLDER/project/dag.py', '--cfg-path', '/tmp/tmpyagkch2t']
[2024-04-12T23:19:00.396+0000] {standard_task_runner.py:88} INFO - Job 9: Subtask print_message
[2024-04-12T23:19:00.440+0000] {task_command.py:423} INFO - Running <TaskInstance: example-docker-operator-dag.print_message manual__2024-04-12T23:18:59.707108+00:00 [running]> on host 54de63e8b577
[2024-04-12T23:19:00.495+0000] {taskinstance.py:2513} INFO - Exporting env vars: AIRFLOW_CTX_DAG_OWNER='***' AIRFLOW_CTX_DAG_ID='example-docker-operator-dag' AIRFLOW_CTX_TASK_ID='print_message' AIRFLOW_CTX_EXECUTION_DATE='2024-04-12T23:18:59.707108+00:00' AIRFLOW_CTX_TRY_NUMBER='1' AIRFLOW_CTX_DAG_RUN_ID='manual__2024-04-12T23:18:59.707108+00:00'
[2024-04-12T23:19:00.507+0000] {docker.py:359} INFO - Starting docker container from image docker-operator-etl:1.0
[2024-04-12T23:19:00.777+0000] {docker.py:429} INFO - python: can't open file '/app/src/main.py': [Errno 2] No such file or directory
[2024-04-12T23:19:01.013+0000] {taskinstance.py:2731} ERROR - Task failed with exception
Traceback (most recent call last):
  File "/home/airflow/.local/lib/python3.8/site-packages/airflow/models/taskinstance.py", line 444, in _execute_task
    result = _execute_callable(context=context, **execute_callable_kwargs)
  File "/home/airflow/.local/lib/python3.8/site-packages/airflow/models/taskinstance.py", line 414, in _execute_callable
    return execute_callable(context=context, **execute_callable_kwargs)
  File "/home/airflow/.local/lib/python3.8/site-packages/airflow/providers/docker/operators/docker.py", line 502, in execute
    return self._run_image()
  File "/home/airflow/.local/lib/python3.8/site-packages/airflow/providers/docker/operators/docker.py", line 376, in _run_image
    return self._run_image_with_mounts(self.mounts, add_tmp_variable=False)
  File "/home/airflow/.local/lib/python3.8/site-packages/airflow/providers/docker/operators/docker.py", line 437, in _run_image_with_mounts
    raise DockerContainerFailedException(f"Docker container failed: {result!r}", logs=log_lines)
airflow.providers.docker.exceptions.DockerContainerFailedException: Docker container failed: {'StatusCode': 2}
[2024-04-12T23:19:01.015+0000] {taskinstance.py:1149} INFO - Marking task as FAILED. dag_id=example-docker-operator-dag, task_id=print_message, execution_date=20240412T231859, start_date=20240412T231900, end_date=20240412T231901
[2024-04-12T23:19:01.024+0000] {standard_task_runner.py:107} ERROR - Failed to execute job 9 for task print_message (Docker container failed: {'StatusCode': 2}; 1166)
[2024-04-12T23:19:01.049+0000] {local_task_job_runner.py:234} INFO - Task exited with return code 1
[2024-04-12T23:19:01.068+0000] {taskinstance.py:3312} INFO - 0 downstream tasks scheduled from follow-on schedule check
